<?xml version="1.0"?>
<robot name="spyndra">
  <gazebo>
    <plugin name="gazebo_ros_control" filename="libgazebo_ros_control.so">
      <robotNamespace>/spyndra</robotNamespace>
    </plugin>
  </gazebo>
  
  <gazebo>
    <plugin name="imu_plugin" filename="libgazebo_ros_imu.so">
      <alwaysOn>true</alwaysOn>
      <bodyName>base_link</bodyName>
      <topicName>imu</topicName>
      <serviceName>imu_service</serviceName>
      <gaussianNoise>0.0</gaussianNoise>
      <updateRate>20.0</updateRate>
    </plugin>
  </gazebo>

  <gazebo reference="base_link">
    <selfCollide>true</selfCollide>
  </gazebo>

  <gazebo reference="femur_1">
    <selfCollide>true</selfCollide>
  </gazebo>

  <gazebo reference="femur_2">
    <selfCollide>true</selfCollide>
  </gazebo>

  <gazebo reference="femur_3">
    <selfCollide>true</selfCollide>
  </gazebo>

  <gazebo reference="femur_4">
    <selfCollide>true</selfCollide>
  </gazebo>

  <gazebo reference="tibia_1">
    <selfCollide>true</selfCollide>
  </gazebo>

  <gazebo reference="tibia_2">
    <selfCollide>true</selfCollide>
  </gazebo>

  <gazebo reference="tibia_3">
    <selfCollide>true</selfCollide>
  </gazebo>

  <gazebo reference="tibia_4">
    <selfCollide>true</selfCollide>
  </gazebo>

  <link name="base_link">
    <visual>
      <geometry>
        <mesh filename="package://spyndra_description/meshes/chassis.stl"/>
      </geometry>
      <origin rpy="0 0 0" xyz="0 0 0"/>
    </visual>
    <collision>
      <geometry>
        <mesh filename="package://spyndra_description/meshes/chassis_col.stl"/>
      </geometry>
      <origin rpy="0 0 0" xyz="0 0 0"/>
    </collision>
    <inertial>
      <origin xyz="0 0 0" rpy="0 0 0"/>
      <mass value="1"/>
      <inertia
        ixx="0.084981" ixy="0.000124" ixz="-0.000077"
        iyy="0.083196" iyz="-0.000128"
        izz="0.099084"/>
    </inertial>
  </link>

  <link name="femur_1">
    <visual>
      <geometry>
        <mesh filename="package://spyndra_description/meshes/femur.stl"/>
      </geometry>
      <origin rpy="0 0 0" xyz="0.4 0 0"/>
    </visual>
    <collision>
      <geometry>
        <mesh filename="package://spyndra_description/meshes/femur_col.stl"/>
      </geometry>
      <origin rpy="0 0 0" xyz="0.4 0 0"/>
    </collision>
    <inertial>
      <origin rpy="0 0 0" xyz="0.4 0 0"/>
      <mass value="0.2"/>
      <inertia
        ixx="0.001433" ixy="0.000000" ixz="0.000000"
        iyy="0.004311" iyz="0.000000"
        izz="0.004255"/>
    </inertial>
  </link>

  <link name="femur_2">
    <visual>
      <geometry>
        <mesh filename="package://spyndra_description/meshes/femur.stl"/>
      </geometry>
      <origin rpy="0 0 1.57075" xyz="0 0.4 0"/>
    </visual>
    <collision>
      <geometry>
        <mesh filename="package://spyndra_description/meshes/femur_col.stl"/>
      </geometry>
      <origin rpy="0 0 1.57075" xyz="0 0.4 0"/>
    </collision>
    <inertial>
      <origin rpy="0 0 1.57075" xyz="0 0.4 0"/>
      <mass value="0.2"/>
      <inertia
        ixx="0.001433" ixy="0.000000" ixz="0.000000"
        iyy="0.004311" iyz="0.000000"
        izz="0.004255"/>
    </inertial>
  </link>

  <link name="femur_3">
    <visual>
      <geometry>
        <mesh filename="package://spyndra_description/meshes/femur.stl"/>
      </geometry>
      <origin rpy="0 0 3.1415" xyz="-0.4 0 0"/>
    </visual>
    <collision>
      <geometry>
        <mesh filename="package://spyndra_description/meshes/femur_col.stl"/>
      </geometry>
      <origin rpy="0 -0 3.1415" xyz="-0.4 0 0"/>
    </collision>
    <inertial>
      <origin rpy="0 0 3.1415" xyz="-0.4 0 0"/>
      <mass value="0.2"/>
      <inertia
        ixx="0.001433" ixy="0.000000" ixz="0.000000"
        iyy="0.004311" iyz="0.000000"
        izz="0.004255"/>
    </inertial>
  </link>

  <link name="femur_4">
    <visual>
      <geometry>
        <mesh filename="package://spyndra_description/meshes/femur.stl"/>
      </geometry>
      <origin rpy="0 0 -1.57075" xyz="0 -0.4 0"/>
    </visual>
    <collision>
      <geometry>
        <mesh filename="package://spyndra_description/meshes/femur_col.stl"/>
      </geometry>
      <origin rpy="0 0 -1.57075" xyz="0 -0.4 0"/>
    </collision>
    <inertial>
      <origin rpy="0 0 -1.57075" xyz="0 -0.4 0"/>
      <mass value="0.2"/>
      <inertia
        ixx="0.001433" ixy="0.000000" ixz="0.000000"
        iyy="0.004311" iyz="0.000000"
        izz="0.004255"/>
    </inertial>
  </link>

  <link name="tibia_1">
    <visual>
      <geometry>
        <mesh filename="package://spyndra_description/meshes/tibia.stl"/>
      </geometry>
      <origin rpy="1.57075 0 -1.57075" xyz="0.8 0 0.2"/>
    </visual>
    <collision>
      <geometry>
        <mesh filename="package://spyndra_description/meshes/tibia_col.stl"/>
      </geometry>
      <origin rpy="1.57075 0 -1.57075" xyz="0.8 0 0.2"/>
    </collision>
    <inertial>
      <origin rpy="1.57075 0 -1.57075" xyz="0.8 0 0.2"/>
      <mass value="0.1"/>
      <inertia
        ixx="0.012986" ixy="0.000000" ixz="0.000000"
        iyy="0.012051" iyz="0.003922"
        izz="0.002521"/>
    </inertial>
  </link>

  <link name="tibia_2">
    <visual>
      <geometry>
        <mesh filename="package://spyndra_description/meshes/tibia.stl"/>
      </geometry>
      <origin rpy="1.57075 0 0" xyz="0 0.8 0.2"/>
    </visual>
    <collision>
      <geometry>
        <mesh filename="package://spyndra_description/meshes/tibia_col.stl"/>
      </geometry>
      <origin rpy="1.57075 0 0" xyz="0 0.8 0.2"/>
    </collision>
    <inertial>
      <origin rpy="1.57075 0 0" xyz="0 0.8 0.2"/>
      <mass value="0.1"/>
      <inertia
        ixx="0.012986" ixy="0.000000" ixz="0.000000"
        iyy="0.012051" iyz="0.003922"
        izz="0.002521"/>
    </inertial>
  </link>

  <link name="tibia_3">
    <visual>
      <geometry>
        <mesh filename="package://spyndra_description/meshes/tibia.stl"/>
      </geometry>
      <origin rpy="1.57075 0 1.57075" xyz="-0.8 0 0.2"/>
    </visual>
    <collision>
      <geometry>
        <mesh filename="package://spyndra_description/meshes/tibia_col.stl"/>
      </geometry>
      <origin rpy="1.57075 0 1.57075" xyz="-0.8 0 0.2"/>
    </collision>
    <inertial>
      <origin rpy="1.57075 0 1.57075" xyz="-0.8 0 0.2"/>
      <mass value="0.1"/>
      <inertia
        ixx="0.012986" ixy="0.000000" ixz="0.000000"
        iyy="0.012051" iyz="0.003922"
        izz="0.002521"/>
    </inertial>
  </link>

  <link name="tibia_4">
    <visual>
      <geometry>
        <mesh filename="package://spyndra_description/meshes/tibia.stl"/>
      </geometry>
      <origin rpy="1.57075 0 3.1415" xyz="0 -0.8 0.2"/>
    </visual>
    <collision>
      <geometry>
        <mesh filename="package://spyndra_description/meshes/tibia_col.stl"/>
      </geometry>
      <origin rpy="1.57075 0 3.1415" xyz="0 -0.8 0.2"/>
    </collision>
    <inertial>
      <origin rpy="1.57075 0 3.1415" xyz="0 -0.8 0.2"/>
      <mass value="0.1"/>
      <inertia
        ixx="0.012986" ixy="0.000000" ixz="0.000000"
        iyy="0.012051" iyz="0.003922"
        izz="0.002521"/>
    </inertial>
  </link>

  <joint name="base_to_femur_1" type="revolute">
    <origin rpy="0 0 0" xyz="0.9 0 -0.2"/>
    <axis xyz="0 1 0"/>
    <limit effort="1000.0" lower="-1.5" upper="1.5" velocity="0.1"/>
    <parent link="base_link"/>
    <child link="femur_1"/>
  </joint>

  <joint name="base_to_femur_2" type="revolute">
    <origin rpy="0 0 0" xyz="0 0.9 -0.2"/>
    <axis xyz="-1 0 0"/>
    <limit effort="1000.0" lower="-1.5" upper="1.5" velocity="0.1"/>
    <parent link="base_link"/>
    <child link="femur_2"/>
  </joint>

  <joint name="base_to_femur_3" type="revolute">
    <origin rpy="0 0 0" xyz="-0.9 0 -0.2"/>
    <axis xyz="0 -1 0"/>
    <limit effort="1000.0" lower="-1.5" upper="1.5" velocity="0.1"/>
    <parent link="base_link"/>
    <child link="femur_3"/>
  </joint>

  <joint name="base_to_femur_4" type="revolute">
    <origin rpy="0 0 0" xyz="0 -0.9 -0.2"/>
    <axis xyz="1 0 0"/>
    <limit effort="1000.0" lower="-1.5" upper="1.5" velocity="0.1"/>
    <parent link="base_link"/>
    <child link="femur_4"/>
  </joint>

  <joint name="femur_to_tibia_1" type="revolute">
    <origin rpy="0 0 0" xyz="0.8 0 0"/>
    <axis xyz="0 1 0"/>
    <limit effort="1000.0" lower="-1.5" upper="1.5" velocity="0.1"/>
    <parent link="femur_1"/>
    <child link="tibia_1"/>
  </joint>

  <joint name="femur_to_tibia_2" type="revolute">
    <origin rpy="0 0 0" xyz="0 0.8 0"/>
    <axis xyz="-1 0 0"/>
    <limit effort="1000.0" lower="-1.5" upper="1.5" velocity="0.1"/>
    <parent link="femur_2"/>
    <child link="tibia_2"/>
  </joint>

  <joint name="femur_to_tibia_3" type="revolute">
    <origin rpy="0 0 0" xyz="-0.8 0 0"/>
    <axis xyz="0 -1 0"/>
    <limit effort="1000.0" lower="-1.5" upper="1.5" velocity="0.1"/>
    <parent link="femur_3"/>
    <child link="tibia_3"/>
  </joint>

  <joint name="femur_to_tibia_4" type="revolute">
    <origin rpy="0 0 0" xyz="0 -0.8 0"/>
    <axis xyz="1 0 0"/>
    <limit effort="1000.0" lower="-1.5" upper="1.5" velocity="0.1"/>
    <parent link="femur_4"/>
    <child link="tibia_4"/>
  </joint>

  <transmission name="tran1">
    <type>transmission_interface/SimpleTransmission</type>
    <joint name="base_to_femur_1">
      <hardwareInterface>EffortJointInterface</hardwareInterface>
    </joint>
    <actuator name="motor1">
      <hardwareInterface>EffortJointInterface</hardwareInterface>
      <mechanicalReduction>1</mechanicalReduction>
    </actuator>
  </transmission>

  <transmission name="tran2">
    <type>transmission_interface/SimpleTransmission</type>
    <joint name="base_to_femur_2">
      <hardwareInterface>EffortJointInterface</hardwareInterface>
    </joint>
    <actuator name="motor2">
      <hardwareInterface>EffortJointInterface</hardwareInterface>
      <mechanicalReduction>1</mechanicalReduction>
    </actuator>
  </transmission>

  <transmission name="tran3">
    <type>transmission_interface/SimpleTransmission</type>
    <joint name="base_to_femur_3">
      <hardwareInterface>EffortJointInterface</hardwareInterface>
    </joint>
    <actuator name="motor3">
      <hardwareInterface>EffortJointInterface</hardwareInterface>
      <mechanicalReduction>1</mechanicalReduction>
    </actuator>
  </transmission>

  <transmission name="tran4">
    <type>transmission_interface/SimpleTransmission</type>
    <joint name="base_to_femur_4">
      <hardwareInterface>EffortJointInterface</hardwareInterface>
    </joint>
    <actuator name="motor4">
      <hardwareInterface>EffortJointInterface</hardwareInterface>
      <mechanicalReduction>1</mechanicalReduction>
    </actuator>
  </transmission>

  <transmission name="tran5">
    <type>transmission_interface/SimpleTransmission</type>
    <joint name="femur_to_tibia_1">
      <hardwareInterface>EffortJointInterface</hardwareInterface>
    </joint>
    <actuator name="motor5">
      <hardwareInterface>EffortJointInterface</hardwareInterface>
      <mechanicalReduction>1</mechanicalReduction>
    </actuator>
  </transmission>

  <transmission name="tran6">
    <type>transmission_interface/SimpleTransmission</type>
    <joint name="femur_to_tibia_2">
      <hardwareInterface>EffortJointInterface</hardwareInterface>
    </joint>
    <actuator name="motor6">
      <hardwareInterface>EffortJointInterface</hardwareInterface>
      <mechanicalReduction>1</mechanicalReduction>
    </actuator>
  </transmission>

  <transmission name="tra71">
    <type>transmission_interface/SimpleTransmission</type>
    <joint name="femur_to_tibia_3">
      <hardwareInterface>EffortJointInterface</hardwareInterface>
    </joint>
    <actuator name="motor7">
      <hardwareInterface>EffortJointInterface</hardwareInterface>
      <mechanicalReduction>1</mechanicalReduction>
    </actuator>
  </transmission>

  <transmission name="tran8">
    <type>transmission_interface/SimpleTransmission</type>
    <joint name="femur_to_tibia_4">
      <hardwareInterface>EffortJointInterface</hardwareInterface>
    </joint>
    <actuator name="motor8">
      <hardwareInterface>EffortJointInterface</hardwareInterface>
      <mechanicalReduction>1</mechanicalReduction>
    </actuator>
  </transmission>
</robot>
